Workbook

Sheet Knutepunkter
A1: Navn | B1: X [mm] | C1: Y [mm] | D1: Z [mm]
A2: =IF(AND(FORSIDE!$B$8>=0,FORSIDE!$F$8>=0,FORSIDE!$B$5>=0),1,"") -> 1 | B2: =IF(AND(FORSIDE!$B$8>=0,FORSIDE!$F$8>=0,FORSIDE!$B$5>=0),354+0*FORSIDE!$F$9,"") -> 354 | C2: =IF(AND(FORSIDE!$B$8>=0,FORSIDE!$F$8>=0,FORSIDE!$B$5>=0),0*FORSIDE!$B$9,"") -> 0 | D2: =IF(AND(FORSIDE!$B$8>=0,FORSIDE!$F$8>=0,FORSIDE!$B$5>=0),0,"") -> 0
A3: =IF(AND(FORSIDE!$B$8>=0,FORSIDE!$F$8>=0,FORSIDE!$B$5>=1),2,"") -> 2 | B3: =IF(AND(FORSIDE!$B$8>=0,FORSIDE!$F$8>=0,FORSIDE!$B$5>=1),354+0*FORSIDE!$F$9,"") -> 354 | C3: =IF(AND(FORSIDE!$B$8>=0,FORSIDE!$F$8>=0,FORSIDE!$B$5>=1),0*FORSIDE!$B$9,"") -> 0 | D3: =IF(AND(FORSIDE!$B$8>=0,FORSIDE!$F$8>=0,FORSIDE!$B$5>=1),FORSIDE!$B$6+(1-1)*FORSIDE!$B$7,"") -> 3000
A4: =IF(AND(FORSIDE!$B$8>=0,FORSIDE!$F$8>=0,FORSIDE!$B$5>=2),3,"") -> 3 | B4: =IF(AND(FORSIDE!$B$8>=0,FORSIDE!$F$8>=0,FORSIDE!$B$5>=2),354+0*FORSIDE!$F$9,"") -> 354 | C4: =IF(AND(FORSIDE!$B$8>=0,FORSIDE!$F$8>=0,FORSIDE!$B$5>=2),0*FORSIDE!$B$9,"") -> 0 | D4: =IF(AND(FORSIDE!$B$8>=0,FORSIDE!$F$8>=0,FORSIDE!$B$5>=2),FORSIDE!$B$6+(2-1)*FORSIDE!$B$7,"") -> 6000
A5: =IF(AND(FORSIDE!$B$8>=0,FORSIDE!$F$8>=0,FORSIDE!$B$5>=3),4,"") -> 4 | B5: =IF(AND(FORSIDE!$B$8>=0,FORSIDE!$F$8>=0,FORSIDE!$B$5>=3),354+0*FORSIDE!$F$9,"") -> 354 | C5: =IF(AND(FORSIDE!$B$8>=0,FORSIDE!$F$8>=0,FORSIDE!$B$5>=3),0*FORSIDE!$B$9,"") -> 0 | D5: =IF(AND(FORSIDE!$B$8>=0,FORSIDE!$F$8>=0,FORSIDE!$B$5>=3),FORSIDE!$B$6+(3-1)*FORSIDE!$B$7,"") -> 9000
A6: =IF(AND(FORSIDE!$B$8>=0,FORSIDE!$F$8>=0,FORSIDE!$B$5>=4),5,"") -> 5 | B6: =IF(AND(FORSIDE!$B$8>=0,FORSIDE!$F$8>=0,FORSIDE!$B$5>=4),354+0*FORSIDE!$F$9,"") -> 354 | C6: =IF(AND(FORSIDE!$B$8>=0,FORSIDE!$F$8>=0,FORSIDE!$B$5>=4),0*FORSIDE!$B$9,"") -> 0 | D6: =IF(AND(FORSIDE!$B$8>=0,FORSIDE!$F$8>=0,FORSIDE!$B$5>=4),FORSIDE!$B$6+(4-1)*FORSIDE!$B$7,"") -> 12000
A7: =IF(AND(FORSIDE!$B$8>=0,FORSIDE!$F$8>=0,FORSIDE!$B$5>=5),6,"") -> 6 | B7: =IF(AND(FORSIDE!$B$8>=0,FORSIDE!$F$8>=0,FORSIDE!$B$5>=5),354+0*FORSIDE!$F$9,"") -> 354 | C7: =IF(AND(FORSIDE!$B$8>=0,FORSIDE!$F$8>=0,FORSIDE!$B$5>=5),0*FORSIDE!$B$9,"") -> 0 | D7: =IF(AND(FORSIDE!$B$8>=0,FORSIDE!$F$8>=0,FORSIDE!$B$5>=5),FORSIDE!$B$6+(5-1)*FORSIDE!$B$7,"") -> 15000
A8: =IF(AND(FORSIDE!$B$8>=0,FORSIDE!$F$8>=0,FORSIDE!$B$5>=6),7,"") -> 7 | B8: =IF(AND(FORSIDE!$B$8>=0,FORSIDE!$F$8>=0,FORSIDE!$B$5>=6),354+0*FORSIDE!$F$9,"") -> 354 | C8: =IF(AND(FORSIDE!$B$8>=0,FORSIDE!$F$8>=0,FORSIDE!$B$5>=6),0*FORSIDE!$B$9,"") -> 0 | D8: =IF(AND(FORSIDE!$B$8>=0,FORSIDE!$F$8>=0,FORSIDE!$B$5>=6),FORSIDE!$B$6+(6-1)*FORSIDE!$B$7,"") -> 18000
A9: =IF(AND(FORSIDE!$B$8>=0,FORSIDE!$F$8>=0,FORSIDE!$B$5>=7),8,"") | B9: =IF(AND(FORSIDE!$B$8>=0,FORSIDE!$F$8>=0,FORSIDE!$B$5>=7),354+0*FORSIDE!$F$9,"") | C9: =IF(AND(FORSIDE!$B$8>=0,FORSIDE!$F$8>=0,FORSIDE!$B$5>=7),0*FORSIDE!$B$9,"") | D9: =IF(AND(FORSIDE!$B$8>=0,FORSIDE!$F$8>=0,FORSIDE!$B$5>=7),FORSIDE!$B$6+(7-1)*FORSIDE!$B$7,"")
A10: =IF(AND(FORSIDE!$B$8>=0,FORSIDE!$F$8>=0,FORSIDE!$B$5>=8),9,"") | B10: =IF(AND(FORSIDE!$B$8>=0,FORSIDE!$F$8>=0,FORSIDE!$B$5>=8),354+0*FORSIDE!$F$9,"") | C10: =IF(AND(FORSIDE!$B$8>=0,FORSIDE!$F$8>=0,FORSIDE!$B$5>=8),0*FORSIDE!$B$9,"") | D10: =IF(AND(FORSIDE!$B$8>=0,FORSIDE!$F$8>=0,FORSIDE!$B$5>=8),FORSIDE!$B$6+(8-1)*FORSIDE!$B$7,"")
A11: =IF(AND(FORSIDE!$B$8>=0,FORSIDE!$F$8>=0,FORSIDE!$B$5>=9),10,"") | B11: =IF(AND(FORSIDE!$B$8>=0,FORSIDE!$F$8>=0,FORSIDE!$B$5>=9),354+0*FORSIDE!$F$9,"") | C11: =IF(AND(FORSIDE!$B$8>=0,FORSIDE!$F$8>=0,FORSIDE!$B$5>=9),0*FORSIDE!$B$9,"") | D11: =IF(AND(FORSIDE!$B$8>=0,FORSIDE!$F$8>=0,FORSIDE!$B$5>=9),FORSIDE!$B$6+(9-1)*FORSIDE!$B$7,"")
A12: =IF(AND(FORSIDE!$B$8>=0,FORSIDE!$F$8>=0,FORSIDE!$B$5>=10),11,"") | B12: =IF(AND(FORSIDE!$B$8>=0,FORSIDE!$F$8>=0,FORSIDE!$B$5>=10),354+0*FORSIDE!$F$9,"") | C12: =IF(AND(FORSIDE!$B$8>=0,FORSIDE!$F$8>=0,FORSIDE!$B$5>=10),0*FORSIDE!$B$9,"") | D12: =IF(AND(FORSIDE!$B$8>=0,FORSIDE!$F$8>=0,FORSIDE!$B$5>=10),FORSIDE!$B$6+(10-1)*FORSIDE!$B$7,"")
A13: =IF(AND(FORSIDE!$B$8>=1,FORSIDE!$F$8>=0,FORSIDE!$B$5>=0),12,"") -> 12 | B13: =IF(AND(FORSIDE!$B$8>=1,FORSIDE!$F$8>=0,FORSIDE!$B$5>=0),354+0*FORSIDE!$F$9,"") -> 354 | C13: =IF(AND(FORSIDE!$B$8>=1,FORSIDE!$F$8>=0,FORSIDE!$B$5>=0),1*FORSIDE!$B$9,"") -> 8000 | D13: =IF(AND(FORSIDE!$B$8>=1,FORSIDE!$F$8>=0,FORSIDE!$B$5>=0),0,"") -> 0
A14: =IF(AND(FORSIDE!$B$8>=1,FORSIDE!$F$8>=0,FORSIDE!$B$5>=1),13,"") -> 13 | B14: =IF(AND(FORSIDE!$B$8>=1,FORSIDE!$F$8>=0,FORSIDE!$B$5>=1),354+0*FORSIDE!$F$9,"") -> 354 | C14: =IF(AND(FORSIDE!$B$8>=1,FORSIDE!$F$8>=0,FORSIDE!$B$5>=1),1*FORSIDE!$B$9,"") -> 8000 | D14: =IF(AND(FORSIDE!$B$8>=1,FORSIDE!$F$8>=0,FORSIDE!$B$5>=1),FORSIDE!$B$6+(1-1)*FORSIDE!$B$7,"") -> 3000
A15: =IF(AND(FORSIDE!$B$8>=1,FORSIDE!$F$8>=0,FORSIDE!$B$5>=2),14,"") -> 14 | B15: =IF(AND(FORSIDE!$B$8>=1,FORSIDE!$F$8>=0,FORSIDE!$B$5>=2),354+0*FORSIDE!$F$9,"") -> 354 | C15: =IF(AND(FORSIDE!$B$8>=1,FORSIDE!$F$8>=0,FORSIDE!$B$5>=2),1*FORSIDE!$B$9,"") -> 8000 | D15: =IF(AND(FORSIDE!$B$8>=1,FORSIDE!$F$8>=0,FORSIDE!$B$5>=2),FORSIDE!$B$6+(2-1)*FORSIDE!$B$7,"") -> 6000
A16: =IF(AND(FORSIDE!$B$8>=1,FORSIDE!$F$8>=0,FORSIDE!$B$5>=3),15,"") -> 15 | B16: =IF(AND(FORSIDE!$B$8>=1,FORSIDE!$F$8>=0,FORSIDE!$B$5>=3),354+0*FORSIDE!$F$9,"") -> 354 | C16: =IF(AND(FORSIDE!$B$8>=1,FORSIDE!$F$8>=0,FORSIDE!$B$5>=3),1*FORSIDE!$B$9,"") -> 8000 | D16: =IF(AND(FORSIDE!$B$8>=1,FORSIDE!$F$8>=0,FORSIDE!$B$5>=3),FORSIDE!$B$6+(3-1)*FORSIDE!$B$7,"") -> 9000
A17: =IF(AND(FORSIDE!$B$8>=1,FORSIDE!$F$8>=0,FORSIDE!$B$5>=4),16,"") -> 16 | B17: =IF(AND(FORSIDE!$B$8>=1,FORSIDE!$F$8>=0,FORSIDE!$B$5>=4),354+0*FORSIDE!$F$9,"") -> 354 | C17: =IF(AND(FORSIDE!$B$8>=1,FORSIDE!$F$8>=0,FORSIDE!$B$5>=4),1*FORSIDE!$B$9,"") -> 8000 | D17: =IF(AND(FORSIDE!$B$8>=1,FORSIDE!$F$8>=0,FORSIDE!$B$5>=4),FORSIDE!$B$6+(4-1)*FORSIDE!$B$7,"") -> 12000
A18: =IF(AND(FORSIDE!$B$8>=1,FORSIDE!$F$8>=0,FORSIDE!$B$5>=5),17,"") -> 17 | B18: =IF(AND(FORSIDE!$B$8>=1,FORSIDE!$F$8>=0,FORSIDE!$B$5>=5),354+0*FORSIDE!$F$9,"") -> 354 | C18: =IF(AND(FORSIDE!$B$8>=1,FORSIDE!$F$8>=0,FORSIDE!$B$5>=5),1*FORSIDE!$B$9,"") -> 8000 | D18: =IF(AND(FORSIDE!$B$8>=1,FORSIDE!$F$8>=0,FORSIDE!$B$5>=5),FORSIDE!$B$6+(5-1)*FORSIDE!$B$7,"") -> 15000
A19: =IF(AND(FORSIDE!$B$8>=1,FORSIDE!$F$8>=0,FORSIDE!$B$5>=6),18,"") -> 18 | B19: =IF(AND(FORSIDE!$B$8>=1,FORSIDE!$F$8>=0,FORSIDE!$B$5>=6),354+0*FORSIDE!$F$9,"") -> 354 | C19: =IF(AND(FORSIDE!$B$8>=1,FORSIDE!$F$8>=0,FORSIDE!$B$5>=6),1*FORSIDE!$B$9,"") -> 8000 | D19: =IF(AND(FORSIDE!$B$8>=1,FORSIDE!$F$8>=0,FORSIDE!$B$5>=6),FORSIDE!$B$6+(6-1)*FORSIDE!$B$7,"") -> 18000
A20: =IF(AND(FORSIDE!$B$8>=1,FORSIDE!$F$8>=0,FORSIDE!$B$5>=7),19,"") | B20: =IF(AND(FORSIDE!$B$8>=1,FORSIDE!$F$8>=0,FORSIDE!$B$5>=7),354+0*FORSIDE!$F$9,"") | C20: =IF(AND(FORSIDE!$B$8>=1,FORSIDE!$F$8>=0,FORSIDE!$B$5>=7),1*FORSIDE!$B$9,"") | D20: =IF(AND(FORSIDE!$B$8>=1,FORSIDE!$F$8>=0,FORSIDE!$B$5>=7),FORSIDE!$B$6+(7-1)*FORSIDE!$B$7,"")
A21: =IF(AND(FORSIDE!$B$8>=1,FORSIDE!$F$8>=0,FORSIDE!$B$5>=8),20,"") | B21: =IF(AND(FORSIDE!$B$8>=1,FORSIDE!$F$8>=0,FORSIDE!$B$5>=8),354+0*FORSIDE!$F$9,"") | C21: =IF(AND(FORSIDE!$B$8>=1,FORSIDE!$F$8>=0,FORSIDE!$B$5>=8),1*FORSIDE!$B$9,"") | D21: =IF(AND(FORSIDE!$B$8>=1,FORSIDE!$F$8>=0,FORSIDE!$B$5>=8),FORSIDE!$B$6+(8-1)*FORSIDE!$B$7,"")
A22: =IF(AND(FORSIDE!$B$8>=1,FORSIDE!$F$8>=0,FORSIDE!$B$5>=9),21,"") | B22: =IF(AND(FORSIDE!$B$8>=1,FORSIDE!$F$8>=0,FORSIDE!$B$5>=9),354+0*FORSIDE!$F$9,"") | C22: =IF(AND(FORSIDE!$B$8>=1,FORSIDE!$F$8>=0,FORSIDE!$B$5>=9),1*FORSIDE!$B$9,"") | D22: =IF(AND(FORSIDE!$B$8>=1,FORSIDE!$F$8>=0,FORSIDE!$B$5>=9),FORSIDE!$B$6+(9-1)*FORSIDE!$B$7,"")
A23: =IF(AND(FORSIDE!$B$8>=1,FORSIDE!$F$8>=0,FORSIDE!$B$5>=10),22,"") | B23: =IF(AND(FORSIDE!$B$8>=1,FORSIDE!$F$8>=0,FORSIDE!$B$5>=10),354+0*FORSIDE!$F$9,"") | C23: =IF(AND(FORSIDE!$B$8>=1,FORSIDE!$F$8>=0,FORSIDE!$B$5>=10),1*FORSIDE!$B$9,"") | D23: =IF(AND(FORSIDE!$B$8>=1,FORSIDE!$F$8>=0,FORSIDE!$B$5>=10),FORSIDE!$B$6+(10-1)*FORSIDE!$B$7,"")
A24: =IF(AND(FORSIDE!$B$8>=2,FORSIDE!$F$8>=0,FORSIDE!$B$5>=0),23,"") -> 23 | B24: =IF(AND(FORSIDE!$B$8>=2,FORSIDE!$F$8>=0,FORSIDE!$B$5>=0),354+0*FORSIDE!$F$9,"") -> 354 | C24: =IF(AND(FORSIDE!$B$8>=2,FORSIDE!$F$8>=0,FORSIDE!$B$5>=0),2*FORSIDE!$B$9,"") -> 16000 | D24: =IF(AND(FORSIDE!$B$8>=2,FORSIDE!$F$8>=0,FORSIDE!$B$5>=0),0,"") -> 0
A25: =IF(AND(FORSIDE!$B$8>=2,FORSIDE!$F$8>=0,FORSIDE!$B$5>=1),24,"") -> 24 | B25: =IF(AND(FORSIDE!$B$8>=2,FORSIDE!$F$8>=0,FORSIDE!$B$5>=1),354+0*FORSIDE!$F$9,"") -> 354 | C25: =IF(AND(FORSIDE!$B$8>=2,FORSIDE!$F$8>=0,FORSIDE!$B$5>=1),2*FORSIDE!$B$9,"") -> 16000 | D25: =IF(AND(FORSIDE!$B$8>=2,FORSIDE!$F$8>=0,FORSIDE!$B$5>=1),FORSIDE!$B$6+(1-1)*FORSIDE!$B$7,"") -> 3000
A26: =IF(AND(FORSIDE!$B$8>=2,FORSIDE!$F$8>=0,FORSIDE!$B$5>=2),25,"") -> 25 | B26: =IF(AND(FORSIDE!$B$8>=2,FORSIDE!$F$8>=0,FORSIDE!$B$5>=2),354+0*FORSIDE!$F$9,"") -> 354 | C26: =IF(AND(FORSIDE!$B$8>=2,FORSIDE!$F$8>=0,FORSIDE!$B$5>=2),2*FORSIDE!$B$9,"") -> 16000 | D26: =IF(AND(FORSIDE!$B$8>=2,FORSIDE!$F$8>=0,FORSIDE!$B$5>=2),FORSIDE!$B$6+(2-1)*FORSIDE!$B$7,"") -> 6000
A27: =IF(AND(FORSIDE!$B$8>=2,FORSIDE!$F$8>=0,FORSIDE!$B$5>=3),26,"") -> 26 | B27: =IF(AND(FORSIDE!$B$8>=2,FORSIDE!$F$8>=0,FORSIDE!$B$5>=3),354+0*FORSIDE!$F$9,"") -> 354 | C27: =IF(AND(FORSIDE!$B$8>=2,FORSIDE!$F$8>=0,FORSIDE!$B$5>=3),2*FORSIDE!$B$9,"") -> 16000 | D27: =IF(AND(FORSIDE!$B$8>=2,FORSIDE!$F$8>=0,FORSIDE!$B$5>=3),FORSIDE!$B$6+(3-1)*FORSIDE!$B$7,"") -> 9000
A28: =IF(AND(FORSIDE!$B$8>=2,FORSIDE!$F$8>=0,FORSIDE!$B$5>=4),27,"") -> 27 | B28: =IF(AND(FORSIDE!$B$8>=2,FORSIDE!$F$8>=0,FORSIDE!$B$5>=4),354+0*FORSIDE!$F$9,"") -> 354 | C28: =IF(AND(FORSIDE!$B$8>=2,FORSIDE!$F$8>=0,FORSIDE!$B$5>=4),2*FORSIDE!$B$9,"") -> 16000 | D28: =IF(AND(FORSIDE!$B$8>=2,FORSIDE!$F$8>=0,FORSIDE!$B$5>=4),FORSIDE!$B$6+(4-1)*FORSIDE!$B$7,"") -> 12000
A29: =IF(AND(FORSIDE!$B$8>=2,FORSIDE!$F$8>=0,FORSIDE!$B$5>=5),28,"") -> 28 | B29: =IF(AND(FORSIDE!$B$8>=2,FORSIDE!$F$8>=0,FORSIDE!$B$5>=5),354+0*FORSIDE!$F$9,"") -> 354 | C29: =IF(AND(FORSIDE!$B$8>=2,FORSIDE!$F$8>=0,FORSIDE!$B$5>=5),2*FORSIDE!$B$9,"") -> 16000 | D29: =IF(AND(FORSIDE!$B$8>=2,FORSIDE!$F$8>=0,FORSIDE!$B$5>=5),FORSIDE!$B$6+(5-1)*FORSIDE!$B$7,"") -> 15000
A30: =IF(AND(FORSIDE!$B$8>=2,FORSIDE!$F$8>=0,FORSIDE!$B$5>=6),29,"") -> 29 | B30: =IF(AND(FORSIDE!$B$8>=2,FORSIDE!$F$8>=0,FORSIDE!$B$5>=6),354+0*FORSIDE!$F$9,"") -> 354 | C30: =IF(AND(FORSIDE!$B$8>=2,FORSIDE!$F$8>=0,FORSIDE!$B$5>=6),2*FORSIDE!$B$9,"") -> 16000 | D30: =IF(AND(FORSIDE!$B$8>=2,FORSIDE!$F$8>=0,FORSIDE!$B$5>=6),FORSIDE!$B$6+(6-1)*FORSIDE!$B$7,"") -> 18000
A31: =IF(AND(FORSIDE!$B$8>=2,FORSIDE!$F$8>=0,FORSIDE!$B$5>=7),30,"") | B31: =IF(AND(FORSIDE!$B$8>=2,FORSIDE!$F$8>=0,FORSIDE!$B$5>=7),354+0*FORSIDE!$F$9,"") | C31: =IF(AND(FORSIDE!$B$8>=2,FORSIDE!$F$8>=0,FORSIDE!$B$5>=7),2*FORSIDE!$B$9,"") | D31: =IF(AND(FORSIDE!$B$8>=2,FORSIDE!$F$8>=0,FORSIDE!$B$5>=7),FORSIDE!$B$6+(7-1)*FORSIDE!$B$7,"")
A32: =IF(AND(FORSIDE!$B$8>=2,FORSIDE!$F$8>=0,FORSIDE!$B$5>=8),31,"") | B32: =IF(AND(FORSIDE!$B$8>=2,FORSIDE!$F$8>=0,FORSIDE!$B$5>=8),354+0*FORSIDE!$F$9,"") | C32: =IF(AND(FORSIDE!$B$8>=2,FORSIDE!$F$8>=0,FORSIDE!$B$5>=8),2*FORSIDE!$B$9,"") | D32: =IF(AND(FORSIDE!$B$8>=2,FORSIDE!$F$8>=0,FORSIDE!$B$5>=8),FORSIDE!$B$6+(8-1)*FORSIDE!$B$7,"")
A33: =IF(AND(FORSIDE!$B$8>=2,FORSIDE!$F$8>=0,FORSIDE!$B$5>=9),32,"") | B33: =IF(AND(FORSIDE!$B$8>=2,FORSIDE!$F$8>=0,FORSIDE!$B$5>=9),354+0*FORSIDE!$F$9,"") | C33: =IF(AND(FORSIDE!$B$8>=2,FORSIDE!$F$8>=0,FORSIDE!$B$5>=9),2*FORSIDE!$B$9,"") | D33: =IF(AND(FORSIDE!$B$8>=2,FORSIDE!$F$8>=0,FORSIDE!$B$5>=9),FORSIDE!$B$6+(9-1)*FORSIDE!$B$7,"")
A34: =IF(AND(FORSIDE!$B$8>=2,FORSIDE!$F$8>=0,FORSIDE!$B$5>=10),33,"") | B34: =IF(AND(FORSIDE!$B$8>=2,FORSIDE!$F$8>=0,FORSIDE!$B$5>=10),354+0*FORSIDE!$F$9,"") | C34: =IF(AND(FORSIDE!$B$8>=2,FORSIDE!$F$8>=0,FORSIDE!$B$5>=10),2*FORSIDE!$B$9,"") | D34: =IF(AND(FORSIDE!$B$8>=2,FORSIDE!$F$8>=0,FORSIDE!$B$5>=10),FORSIDE!$B$6+(10-1)*FORSIDE!$B$7,"")
A35: =IF(AND(FORSIDE!$B$8>=3,FORSIDE!$F$8>=0,FORSIDE!$B$5>=0),34,"") -> 34 | B35: =IF(AND(FORSIDE!$B$8>=3,FORSIDE!$F$8>=0,FORSIDE!$B$5>=0),354+0*FORSIDE!$F$9,"") -> 354 | C35: =IF(AND(FORSIDE!$B$8>=3,FORSIDE!$F$8>=0,FORSIDE!$B$5>=0),3*FORSIDE!$B$9,"") -> 24000 | D35: =IF(AND(FORSIDE!$B$8>=3,FORSIDE!$F$8>=0,FORSIDE!$B$5>=0),0,"") -> 0
A36: =IF(AND(FORSIDE!$B$8>=3,FORSIDE!$F$8>=0,FORSIDE!$B$5>=1),35,"") -> 35 | B36: =IF(AND(FORSIDE!$B$8>=3,FORSIDE!$F$8>=0,FORSIDE!$B$5>=1),354+0*FORSIDE!$F$9,"") -> 354 | C36: =IF(AND(FORSIDE!$B$8>=3,FORSIDE!$F$8>=0,FORSIDE!$B$5>=1),3*FORSIDE!$B$9,"") -> 24000 | D36: =IF(AND(FORSIDE!$B$8>=3,FORSIDE!$F$8>=0,FORSIDE!$B$5>=1),FORSIDE!$B$6+(1-1)*FORSIDE!$B$7,"") -> 3000
A37: =IF(AND(FORSIDE!$B$8>=3,FORSIDE!$F$8>=0,FORSIDE!$B$5>=2),36,"") -> 36 | B37: =IF(AND(FORSIDE!$B$8>=3,FORSIDE!$F$8>=0,FORSIDE!$B$5>=2),354+0*FORSIDE!$F$9,"") -> 354 | C37: =IF(AND(FORSIDE!$B$8>=3,FORSIDE!$F$8>=0,FORSIDE!$B$5>=2),3*FORSIDE!$B$9,"") -> 24000 | D37: =IF(AND(FORSIDE!$B$8>=3,FORSIDE!$F$8>=0,FORSIDE!$B$5>=2),FORSIDE!$B$6+(2-1)*FORSIDE!$B$7,"") -> 6000
A38: =IF(AND(FORSIDE!$B$8>=3,FORSIDE!$F$8>=0,FORSIDE!$B$5>=3),37,"") -> 37 | B38: =IF(AND(FORSIDE!$B$8>=3,FORSIDE!$F$8>=0,FORSIDE!$B$5>=3),354+0*FORSIDE!$F$9,"") -> 354 | C38: =IF(AND(FORSIDE!$B$8>=3,FORSIDE!$F$8>=0,FORSIDE!$B$5>=3),3*FORSIDE!$B$9,"") -> 24000 | D38: =IF(AND(FORSIDE!$B$8>=3,FORSIDE!$F$8>=0,FORSIDE!$B$5>=3),FORSIDE!$B$6+(3-1)*FORSIDE!$B$7,"") -> 9000
A39: =IF(AND(FORSIDE!$B$8>=3,FORSIDE!$F$8>=0,FORSIDE!$B$5>=4),38,"") -> 38 | B39: =IF(AND(FORSIDE!$B$8>=3,FORSIDE!$F$8>=0,FORSIDE!$B$5>=4),354+0*FORSIDE!$F$9,"") -> 354 | C39: =IF(AND(FORSIDE!$B$8>=3,FORSIDE!$F$8>=0,FORSIDE!$B$5>=4),3*FORSIDE!$B$9,"") -> 24000 | D39: =IF(AND(FORSIDE!$B$8>=3,FORSIDE!$F$8>=0,FORSIDE!$B$5>=4),FORSIDE!$B$6+(4-1)*FORSIDE!$B$7,"") -> 12000
A40: =IF(AND(FORSIDE!$B$8>=3,FORSIDE!$F$8>=0,FORSIDE!$B$5>=5),39,"") -> 39 | B40: =IF(AND(FORSIDE!$B$8>=3,FORSIDE!$F$8>=0,FORSIDE!$B$5>=5),354+0*FORSIDE!$F$9,"") -> 354 | C40: =IF(AND(FORSIDE!$B$8>=3,FORSIDE!$F$8>=0,FORSIDE!$B$5>=5),3*FORSIDE!$B$9,"") -> 24000 | D40: =IF(AND(FORSIDE!$B$8>=3,FORSIDE!$F$8>=0,FORSIDE!$B$5>=5),FORSIDE!$B$6+(5-1)*FORSIDE!$B$7,"") -> 15000
...

Sheet Segmenter
A1: Navn | B1: Knutepunkter | C1: Material / Tverrsnitt
A2: =IF(AND(FORSIDE!$B$8>=0,FORSIDE!$F$8>=0,FORSIDE!$B$5>=1),"S1","") -> S1 | B2: =IF(AND(FORSIDE!$B$8>=0,FORSIDE!$F$8>=0,FORSIDE!$B$5>=1),"1 -> 2","") -> 1 -> 2 | C2: =FORSIDE!$C$4 -> S355, Stål / KFHUP 180x180x12.5
A3: =IF(AND(FORSIDE!$B$8>=0,FORSIDE!$F$8>=0,FORSIDE!$B$5>=2),"S2","") -> S2 | B3: =IF(AND(FORSIDE!$B$8>=0,FORSIDE!$F$8>=0,FORSIDE!$B$5>=2),"2 -> 3","") -> 2 -> 3 | C3: =FORSIDE!$C$4 -> S355, Stål / KFHUP 180x180x12.5
A4: =IF(AND(FORSIDE!$B$8>=0,FORSIDE!$F$8>=0,FORSIDE!$B$5>=3),"S3","") -> S3 | B4: =IF(AND(FORSIDE!$B$8>=0,FORSIDE!$F$8>=0,FORSIDE!$B$5>=3),"3 -> 4","") -> 3 -> 4 | C4: =FORSIDE!$C$4 -> S355, Stål / KFHUP 180x180x12.5
A5: =IF(AND(FORSIDE!$B$8>=0,FORSIDE!$F$8>=0,FORSIDE!$B$5>=4),"S4","") -> S4 | B5: =IF(AND(FORSIDE!$B$8>=0,FORSIDE!$F$8>=0,FORSIDE!$B$5>=4),"4 -> 5","") -> 4 -> 5 | C5: =FORSIDE!$C$4 -> S355, Stål / KFHUP 180x180x12.5
A6: =IF(AND(FORSIDE!$B$8>=0,FORSIDE!$F$8>=0,FORSIDE!$B$5>=5),"S5","") -> S5 | B6: =IF(AND(FORSIDE!$B$8>=0,FORSIDE!$F$8>=0,FORSIDE!$B$5>=5),"5 -> 6","") -> 5 -> 6 | C6: =FORSIDE!$C$4 -> S355, Stål / KFHUP 180x180x12.5
A7: =IF(AND(FORSIDE!$B$8>=0,FORSIDE!$F$8>=0,FORSIDE!$B$5>=6),"S6","") -> S6 | B7: =IF(AND(FORSIDE!$B$8>=0,FORSIDE!$F$8>=0,FORSIDE!$B$5>=6),"6 -> 7","") -> 6 -> 7 | C7: =FORSIDE!$C$4 -> S355, Stål / KFHUP 180x180x12.5
A8: =IF(AND(FORSIDE!$B$8>=0,FORSIDE!$F$8>=0,FORSIDE!$B$5>=7),"S7","") | B8: =IF(AND(FORSIDE!$B$8>=0,FORSIDE!$F$8>=0,FORSIDE!$B$5>=7),"7 -> 8","") | C8: =FORSIDE!$C$4 -> S355, Stål / KFHUP 180x180x12.5
A9: =IF(AND(FORSIDE!$B$8>=0,FORSIDE!$F$8>=0,FORSIDE!$B$5>=8),"S8","") | B9: =IF(AND(FORSIDE!$B$8>=0,FORSIDE!$F$8>=0,FORSIDE!$B$5>=8),"8 -> 9","") | C9: =FORSIDE!$C$4 -> S355, Stål / KFHUP 180x180x12.5
A10: =IF(AND(FORSIDE!$B$8>=0,FORSIDE!$F$8>=0,FORSIDE!$B$5>=9),"S9","") | B10: =IF(AND(FORSIDE!$B$8>=0,FORSIDE!$F$8>=0,FORSIDE!$B$5>=9),"9 -> 10","") | C10: =FORSIDE!$C$4 -> S355, Stål / KFHUP 180x180x12.5
A11: =IF(AND(FORSIDE!$B$8>=0,FORSIDE!$F$8>=0,FORSIDE!$B$5>=10),"S10","") | B11: =IF(AND(FORSIDE!$B$8>=0,FORSIDE!$F$8>=0,FORSIDE!$B$5>=10),"10 -> 11","") | C11: =FORSIDE!$C$4 -> S355, Stål / KFHUP 180x180x12.5
A12: =IF(AND(FORSIDE!$B$8>=1,FORSIDE!$F$8>=0,FORSIDE!$B$5>=1),"S11","") -> S11 | B12: =IF(AND(FORSIDE!$B$8>=1,FORSIDE!$F$8>=0,FORSIDE!$B$5>=1),"12 -> 13","") -> 12 -> 13 | C12: =FORSIDE!$C$4 -> S355, Stål / KFHUP 180x180x12.5
A13: =IF(AND(FORSIDE!$B$8>=1,FORSIDE!$F$8>=0,FORSIDE!$B$5>=2),"S12","") -> S12 | B13: =IF(AND(FORSIDE!$B$8>=1,FORSIDE!$F$8>=0,FORSIDE!$B$5>=2),"13 -> 14","") -> 13 -> 14 | C13: =FORSIDE!$C$4 -> S355, Stål / KFHUP 180x180x12.5
A14: =IF(AND(FORSIDE!$B$8>=1,FORSIDE!$F$8>=0,FORSIDE!$B$5>=3),"S13","") -> S13 | B14: =IF(AND(FORSIDE!$B$8>=1,FORSIDE!$F$8>=0,FORSIDE!$B$5>=3),"14 -> 15","") -> 14 -> 15 | C14: =FORSIDE!$C$4 -> S355, Stål / KFHUP 180x180x12.5
A15: =IF(AND(FORSIDE!$B$8>=1,FORSIDE!$F$8>=0,FORSIDE!$B$5>=4),"S14","") -> S14 | B15: =IF(AND(FORSIDE!$B$8>=1,FORSIDE!$F$8>=0,FORSIDE!$B$5>=4),"15 -> 16","") -> 15 -> 16 | C15: =FORSIDE!$C$4 -> S355, Stål / KFHUP 180x180x12.5
A16: =IF(AND(FORSIDE!$B$8>=1,FORSIDE!$F$8>=0,FORSIDE!$B$5>=5),"S15","") -> S15 | B16: =IF(AND(FORSIDE!$B$8>=1,FORSIDE!$F$8>=0,FORSIDE!$B$5>=5),"16 -> 17","") -> 16 -> 17 | C16: =FORSIDE!$C$4 -> S355, Stål / KFHUP 180x180x12.5
A17: =IF(AND(FORSIDE!$B$8>=1,FORSIDE!$F$8>=0,FORSIDE!$B$5>=6),"S16","") -> S16 | B17: =IF(AND(FORSIDE!$B$8>=1,FORSIDE!$F$8>=0,FORSIDE!$B$5>=6),"17 -> 18","") -> 17 -> 18 | C17: =FORSIDE!$C$4 -> S355, Stål / KFHUP 180x180x12.5
A18: =IF(AND(FORSIDE!$B$8>=1,FORSIDE!$F$8>=0,FORSIDE!$B$5>=7),"S17","") | B18: =IF(AND(FORSIDE!$B$8>=1,FORSIDE!$F$8>=0,FORSIDE!$B$5>=7),"18 -> 19","") | C18: =FORSIDE!$C$4 -> S355, Stål / KFHUP 180x180x12.5
A19: =IF(AND(FORSIDE!$B$8>=1,FORSIDE!$F$8>=0,FORSIDE!$B$5>=8),"S18","") | B19: =IF(AND(FORSIDE!$B$8>=1,FORSIDE!$F$8>=0,FORSIDE!$B$5>=8),"19 -> 20","") | C19: =FORSIDE!$C$4 -> S355, Stål / KFHUP 180x180x12.5
A20: =IF(AND(FORSIDE!$B$8>=1,FORSIDE!$F$8>=0,FORSIDE!$B$5>=9),"S19","") | B20: =IF(AND(FORSIDE!$B$8>=1,FORSIDE!$F$8>=0,FORSIDE!$B$5>=9),"20 -> 21","") | C20: =FORSIDE!$C$4 -> S355, Stål / KFHUP 180x180x12.5
A21: =IF(AND(FORSIDE!$B$8>=1,FORSIDE!$F$8>=0,FORSIDE!$B$5>=10),"S20","") | B21: =IF(AND(FORSIDE!$B$8>=1,FORSIDE!$F$8>=0,FORSIDE!$B$5>=10),"21 -> 22","") | C21: =FORSIDE!$C$4 -> S355, Stål / KFHUP 180x180x12.5
A22: =IF(AND(FORSIDE!$B$8>=2,FORSIDE!$F$8>=0,FORSIDE!$B$5>=1),"S21","") -> S21 | B22: =IF(AND(FORSIDE!$B$8>=2,FORSIDE!$F$8>=0,FORSIDE!$B$5>=1),"23 -> 24","") -> 23 -> 24 | C22: =FORSIDE!$C$4 -> S355, Stål / KFHUP 180x180x12.5
A23: =IF(AND(FORSIDE!$B$8>=2,FORSIDE!$F$8>=0,FORSIDE!$B$5>=2),"S22","") -> S22 | B23: =IF(AND(FORSIDE!$B$8>=2,FORSIDE!$F$8>=0,FORSIDE!$B$5>=2),"24 -> 25","") -> 24 -> 25 | C23: =FORSIDE!$C$4 -> S355, Stål / KFHUP 180x180x12.5
A24: =IF(AND(FORSIDE!$B$8>=2,FORSIDE!$F$8>=0,FORSIDE!$B$5>=3),"S23","") -> S23 | B24: =IF(AND(FORSIDE!$B$8>=2,FORSIDE!$F$8>=0,FORSIDE!$B$5>=3),"25 -> 26","") -> 25 -> 26 | C24: =FORSIDE!$C$4 -> S355, Stål / KFHUP 180x180x12.5
A25: =IF(AND(FORSIDE!$B$8>=2,FORSIDE!$F$8>=0,FORSIDE!$B$5>=4),"S24","") -> S24 | B25: =IF(AND(FORSIDE!$B$8>=2,FORSIDE!$F$8>=0,FORSIDE!$B$5>=4),"26 -> 27","") -> 26 -> 27 | C25: =FORSIDE!$C$4 -> S355, Stål / KFHUP 180x180x12.5
A26: =IF(AND(FORSIDE!$B$8>=2,FORSIDE!$F$8>=0,FORSIDE!$B$5>=5),"S25","") -> S25 | B26: =IF(AND(FORSIDE!$B$8>=2,FORSIDE!$F$8>=0,FORSIDE!$B$5>=5),"27 -> 28","") -> 27 -> 28 | C26: =FORSIDE!$C$4 -> S355, Stål / KFHUP 180x180x12.5
A27: =IF(AND(FORSIDE!$B$8>=2,FORSIDE!$F$8>=0,FORSIDE!$B$5>=6),"S26","") -> S26 | B27: =IF(AND(FORSIDE!$B$8>=2,FORSIDE!$F$8>=0,FORSIDE!$B$5>=6),"28 -> 29","") -> 28 -> 29 | C27: =FORSIDE!$C$4 -> S355, Stål / KFHUP 180x180x12.5
A28: =IF(AND(FORSIDE!$B$8>=2,FORSIDE!$F$8>=0,FORSIDE!$B$5>=7),"S27","") | B28: =IF(AND(FORSIDE!$B$8>=2,FORSIDE!$F$8>=0,FORSIDE!$B$5>=7),"29 -> 30","") | C28: =FORSIDE!$C$4 -> S355, Stål / KFHUP 180x180x12.5
A29: =IF(AND(FORSIDE!$B$8>=2,FORSIDE!$F$8>=0,FORSIDE!$B$5>=8),"S28","") | B29: =IF(AND(FORSIDE!$B$8>=2,FORSIDE!$F$8>=0,FORSIDE!$B$5>=8),"30 -> 31","") | C29: =FORSIDE!$C$4 -> S355, Stål / KFHUP 180x180x12.5
A30: =IF(AND(FORSIDE!$B$8>=2,FORSIDE!$F$8>=0,FORSIDE!$B$5>=9),"S29","") | B30: =IF(AND(FORSIDE!$B$8>=2,FORSIDE!$F$8>=0,FORSIDE!$B$5>=9),"31 -> 32","") | C30: =FORSIDE!$C$4 -> S355, Stål / KFHUP 180x180x12.5
A31: =IF(AND(FORSIDE!$B$8>=2,FORSIDE!$F$8>=0,FORSIDE!$B$5>=10),"S30","") | B31: =IF(AND(FORSIDE!$B$8>=2,FORSIDE!$F$8>=0,FORSIDE!$B$5>=10),"32 -> 33","") | C31: =FORSIDE!$C$4 -> S355, Stål / KFHUP 180x180x12.5
A32: =IF(AND(FORSIDE!$B$8>=3,FORSIDE!$F$8>=0,FORSIDE!$B$5>=1),"S31","") -> S31 | B32: =IF(AND(FORSIDE!$B$8>=3,FORSIDE!$F$8>=0,FORSIDE!$B$5>=1),"34 -> 35","") -> 34 -> 35 | C32: =FORSIDE!$C$4 -> S355, Stål / KFHUP 180x180x12.5
A33: =IF(AND(FORSIDE!$B$8>=3,FORSIDE!$F$8>=0,FORSIDE!$B$5>=2),"S32","") -> S32 | B33: =IF(AND(FORSIDE!$B$8>=3,FORSIDE!$F$8>=0,FORSIDE!$B$5>=2),"35 -> 36","") -> 35 -> 36 | C33: =FORSIDE!$C$4 -> S355, Stål / KFHUP 180x180x12.5
A34: =IF(AND(FORSIDE!$B$8>=3,FORSIDE!$F$8>=0,FORSIDE!$B$5>=3),"S33","") -> S33 | B34: =IF(AND(FORSIDE!$B$8>=3,FORSIDE!$F$8>=0,FORSIDE!$B$5>=3),"36 -> 37","") -> 36 -> 37 | C34: =FORSIDE!$C$4 -> S355, Stål / KFHUP 180x180x12.5
A35: =IF(AND(FORSIDE!$B$8>=3,FORSIDE!$F$8>=0,FORSIDE!$B$5>=4),"S34","") -> S34 | B35: =IF(AND(FORSIDE!$B$8>=3,FORSIDE!$F$8>=0,FORSIDE!$B$5>=4),"37 -> 38","") -> 37 -> 38 | C35: =FORSIDE!$C$4 -> S355, Stål / KFHUP 180x180x12.5
A36: =IF(AND(FORSIDE!$B$8>=3,FORSIDE!$F$8>=0,FORSIDE!$B$5>=5),"S35","") -> S35 | B36: =IF(AND(FORSIDE!$B$8>=3,FORSIDE!$F$8>=0,FORSIDE!$B$5>=5),"38 -> 39","") -> 38 -> 39 | C36: =FORSIDE!$C$4 -> S355, Stål / KFHUP 180x180x12.5
A37: =IF(AND(FORSIDE!$B$8>=3,FORSIDE!$F$8>=0,FORSIDE!$B$5>=6),"S36","") -> S36 | B37: =IF(AND(FORSIDE!$B$8>=3,FORSIDE!$F$8>=0,FORSIDE!$B$5>=6),"39 -> 40","") -> 39 -> 40 | C37: =FORSIDE!$C$4 -> S355, Stål / KFHUP 180x180x12.5
A38: =IF(AND(FORSIDE!$B$8>=3,FORSIDE!$F$8>=0,FORSIDE!$B$5>=7),"S37","") | B38: =IF(AND(FORSIDE!$B$8>=3,FORSIDE!$F$8>=0,FORSIDE!$B$5>=7),"40 -> 41","") | C38: =FORSIDE!$C$4 -> S355, Stål / KFHUP 180x180x12.5
A39: =IF(AND(FORSIDE!$B$8>=3,FORSIDE!$F$8>=0,FORSIDE!$B$5>=8),"S38","") | B39: =IF(AND(FORSIDE!$B$8>=3,FORSIDE!$F$8>=0,FORSIDE!$B$5>=8),"41 -> 42","") | C39: =FORSIDE!$C$4 -> S355, Stål / KFHUP 180x180x12.5
A40: =IF(AND(FORSIDE!$B$8>=3,FORSIDE!$F$8>=0,FORSIDE!$B$5>=9),"S39","") | B40: =IF(AND(FORSIDE!$B$8>=3,FORSIDE!$F$8>=0,FORSIDE!$B$5>=9),"42 -> 43","") | C40: =FORSIDE!$C$4 -> S355, Stål / KFHUP 180x180x12.5
...

Sheet Punktrandbetingelser
A1: Knutepunkt | B1: Dx | C1: Dy | D1: Dz | E1: Rx | F1: Ry | G1: Rz
A2: 1 | B2: SANN | C2: SANN | D2: SANN | E2: SANN | F2: SANN | G2: SANN
A3: 12 | B3: SANN | C3: SANN | D3: SANN | E3: SANN | F3: SANN | G3: SANN
A4: 23 | B4: SANN | C4: SANN | D4: SANN | E4: SANN | F4: SANN | G4: SANN
A5: 34 | B5: SANN | C5: SANN | D5: SANN | E5: SANN | F5: SANN | G5: SANN
A6: 45 | B6: SANN | C6: SANN | D6: SANN | E6: SANN | F6: SANN | G6: SANN
A7: 56 | B7: SANN | C7: SANN | D7: SANN | E7: SANN | F7: SANN | G7: SANN
A8: 67 | B8: SANN | C8: SANN | D8: SANN | E8: SANN | F8: SANN | G8: SANN
A9: 78 | B9: SANN | C9: SANN | D9: SANN | E9: SANN | F9: SANN | G9: SANN
A10: 89 | B10: SANN | C10: SANN | D10: SANN | E10: SANN | F10: SANN | G10: SANN
A11: 100 | B11: SANN | C11: SANN | D11: SANN | E11: SANN | F11: SANN | G11: SANN
A12: 111 | B12: SANN | C12: SANN | D12: SANN | E12: SANN | F12: SANN | G12: SANN
A13: 122 | B13: SANN | C13: SANN | D13: SANN | E13: SANN | F13: SANN | G13: SANN
... A19: 188 | B19: SANN | C19: SANN | D19: SANN | E19: SANN | F19: SANN | G19: SANN

Sheet Lasttilfeller
A1: Navn | B1: Lasttype | C1: Lastvarighet | D1: Langtidsandel | E1: Psi 0 | F1: Psi 1 | G1: Psi 2
A2: Egenlast | B2: Permanent last | C2: Permanent | D2: 1 | E2: 1 | F2: 1 | G2: 1

Sheet Linjelaster
A1: Lasttilfelle | B1: X1 [mm] | C1: Y1 [mm] | D1: Z1 [mm] | E1: X2 [mm] | F1: Y2 [mm] | G1: Z2 [mm] | H1: Retn. X | I1: Retn. Y | J1: Retn. Z | K1: Kraft ende 1 [kN] | L1: Kraft ende 2 [kN] | M1: Moment ende 1 [kN·m] | N1: Moment ende 2 [kN·m]

Sheet Info
A1: Info
A2: Info
A3: Modell: Parametrisk ramme med materialvalg og etasjevalg 1–10. Bredde og fagdeling er låst.
A4: =_xludf.CONCAT("Knutepunkter maks: ",198) -> #NAME?
A5: =_xludf.CONCAT("Segmenter maks: ",430) -> #NAME?
A6: =_xludf.CONCAT("Søylesegmenter maks: ",180) -> #NAME?
A7: =_xludf.CONCAT("Valgt etasjetall: ",FORSIDE!B5) -> #NAME?
A8: =_xludf.CONCAT("Etasjehøyde 1: ",FORSIDE!B6," mm") -> #NAME?
A9: =_xludf.CONCAT("Standard etasjehøyde: ",FORSIDE!B7," mm") -> #NAME?
A10: Beholdt: rektangulær hovedramme og tverrbjelker
A11: Kortsider: beholdt fra forrige korrigerte modell
A12: Kontroll: åpnes i Focus for visuell verifikasjon av toppnivå og høydeplassering
A13: Tillegg: profilvalg og mengdeuttak på FORSIDE.

Sheet QA_IFC_kontroll
A1: Punkt | B1: Resultat
A2: Tiltak | B2: Fjernet dobbelt toppnivå og senket modellen i Z
A3: Fjernet | B3: Alle knutepunkter og segmenter i øverste duplikatlag
A4: Rettet | B4: Basenivå flyttet ned til Z = 0
A5: Beholdt | B5: Rektangulær hovedramme med tverrbjelker
A6: Knutepunkter | B6: 90
A7: Segmenter | B7: 172
A8: Søylesegmenter | B8: 72
A9: Neste kontroll | B9: Sjekk i Focus at toppbjelkene nå kun vises i ett lag og at modellen står lavere i Z

Sheet FORSIDE
A1: PARAMETRISK MATERIALVALG
A3: Bjelker | B3: Stål | C3: =IF(B3="Stål",$B$10,$B$11) -> S355, Stål / VFHUP 140x140x8.0
A4: Søyler | B4: Stål | C4: =IF(B4="Stål",$B$12,$B$13) -> S355, Stål / KFHUP 180x180x12.5
A5: Antall etasjer | B5: 6 | C5: Velg 1–10 etasjer
A6: Etasjehøyde 1 [mm] | B6: 3000
A7: Standard etasjehøyde [mm] | B7: 3000
A8: Antall fag lengde | B8: 4 | C8: Velg 1–20 fag | E8: Antall fag bredde | F8: 2 | G8: Velg 1–10 fag
A9: Faglengde [mm] | B9: 8000 | C9: 1 fag = 4304 mm | E9: Fagbredde [mm] | F9: 12000 | G9: 1 fag = 18004 mm
A10: Bjelker stål | B10: ="S355, Stål / "&$B$19 -> S355, Stål / VFHUP 140x140x8.0
A11: Bjelker limtre | B11: ="GL30c, Limtre / "&$B$20 -> GL30c, Limtre / Limtre 115x585
A12: Søyler stål | B12: ="S355, Stål / "&$B$21 -> S355, Stål / KFHUP 180x180x12.5
A13: Søyler limtre | B13: ="GL30c, Limtre / "&$B$22 -> GL30c, Limtre / Limtre 90x315
A16: Bruk | B16: Velg Stål eller Limtre i B3 og B4. Lagre filen i Excel før import til Focus.
A18: PROFILVALG
A19: Bjelkeprofil stål | B19: VFHUP 140x140x8.0 | C19: Brukes når Bjelker = Stål | D19: Areal bjelke stål [mm2]
A20: Bjelkeprofil limtre | B20: Limtre 115x585 | C20: Brukes når Bjelker = Limtre | D20: Areal bjelke limtre [mm2]
A21: Søyleprofil stål | B21: KFHUP 180x180x12.5 | C21: Brukes når Søyler = Stål | D21: Areal søyle stål [mm2]
A22: Søyleprofil limtre | B22: Limtre 90x315 | C22: Brukes når Søyler = Limtre | D22: Areal søyle limtre [mm2]
A24: MENGDER
A25: Total bjelkelengde [m] | B25: =MENGDER!Q2 -> 1296
A26: Total søylelengde [m] | B26: =MENGDER!Q3 -> 270
A27: Bjelker stål [kg] | B27: =MENGDER!Q4 -> 0
A28: Bjelker limtre [m3] | B28: =MENGDER!Q5 -> 0
A29: Søyler stål [kg] | B29: =MENGDER!Q6 -> 0
A30: Søyler limtre [m3] | B30: =MENGDER!Q7 -> 0
A31: Aktiv bjelkemengde | B31: =IF(B3="Stål",TEXT(B27,"0")&" kg",TEXT(B28,"0.000")&" m3") -> 0 kg
A32: Aktiv søylemengde | B32: =IF(B4="Stål",TEXT(B29,"0")&" kg",TEXT(B30,"0.000")&" m3") -> 0 kg

Sheet MENGDER
A1: Segment | B1: Knutepunkter | C1: Type | D1: P1 | E1: P2 | F1: X1 | G1: Y1 | H1: Z1 | I1: X2 | J1: Y2 | K1: Z2 | L1: Lengde [mm] | M1: Lengde [m] | P1: Oppsummering | Q1: Verdi
A2: =Segmenter!A2 -> S1 | B2: =Segmenter!B2 -> 1 -> 2 | C2: =IF(B2="","",IF(AND(F2=I2,G2=J2,H2<>K2),"Søyle","Bjelke")) -> Søyle | D2: =IF(B2="","",VALUE(LEFT(B2,FIND(" -> ",B2)-1))) -> 1 | E2: =IF(B2="","",VALUE(MID(B2,FIND(" -> ",B2)+4,99))) -> 2 | F2: =IF(D2="","",INDEX(Knutepunkter!$B:$B,D2+1)) -> 354 | G2: =IF(D2="","",INDEX(Knutepunkter!$C:$C,D2+1)) -> 0 | H2: =IF(D2="","",INDEX(Knutepunkter!$D:$D,D2+1)) -> 0 | I2: =IF(E2="","",INDEX(Knutepunkter!$B:$B,E2+1)) -> 354 | J2: =IF(E2="","",INDEX(Knutepunkter!$C:$C,E2+1)) -> 0 | K2: =IF(E2="","",INDEX(Knutepunkter!$D:$D,E2+1)) -> 3000 | L2: =IF(B2="","",SQRT((I2-F2)^2+(J2-G2)^2+(K2-H2)^2)) -> 3000 | M2: =IF(L2="","",L2/1000) -> 3 | P2: Total bjelkelengde [m] | Q2: =SUMIFS(M:M,C:C,"Bjelke",A:A,"<>") -> 1296
A3: =Segmenter!A3 -> S2 | B3: =Segmenter!B3 -> 2 -> 3 | C3: =IF(B3="","",IF(AND(F3=I3,G3=J3,H3<>K3),"Søyle","Bjelke")) -> Søyle | D3: =IF(B3="","",VALUE(LEFT(B3,FIND(" -> ",B3)-1))) -> 2 | E3: =IF(B3="","",VALUE(MID(B3,FIND(" -> ",B3)+4,99))) -> 3 | F3: =IF(D3="","",INDEX(Knutepunkter!$B:$B,D3+1)) -> 354 | G3: =IF(D3="","",INDEX(Knutepunkter!$C:$C,D3+1)) -> 0 | H3: =IF(D3="","",INDEX(Knutepunkter!$D:$D,D3+1)) -> 3000 | I3: =IF(E3="","",INDEX(Knutepunkter!$B:$B,E3+1)) -> 354 | J3: =IF(E3="","",INDEX(Knutepunkter!$C:$C,E3+1)) -> 0 | K3: =IF(E3="","",INDEX(Knutepunkter!$D:$D,E3+1)) -> 6000 | L3: =IF(B3="","",SQRT((I3-F3)^2+(J3-G3)^2+(K3-H3)^2)) -> 3000 | M3: =IF(L3="","",L3/1000) -> 3 | P3: Total søylelengde [m] | Q3: =SUMIFS(M:M,C:C,"Søyle",A:A,"<>") -> 270
A4: =Segmenter!A4 -> S3 | B4: =Segmenter!B4 -> 3 -> 4 | C4: =IF(B4="","",IF(AND(F4=I4,G4=J4,H4<>K4),"Søyle","Bjelke")) -> Søyle | D4: =IF(B4="","",VALUE(LEFT(B4,FIND(" -> ",B4)-1))) -> 3 | E4: =IF(B4="","",VALUE(MID(B4,FIND(" -> ",B4)+4,99))) -> 4 | F4: =IF(D4="","",INDEX(Knutepunkter!$B:$B,D4+1)) -> 354 | G4: =IF(D4="","",INDEX(Knutepunkter!$C:$C,D4+1)) -> 0 | H4: =IF(D4="","",INDEX(Knutepunkter!$D:$D,D4+1)) -> 6000 | I4: =IF(E4="","",INDEX(Knutepunkter!$B:$B,E4+1)) -> 354 | J4: =IF(E4="","",INDEX(Knutepunkter!$C:$C,E4+1)) -> 0 | K4: =IF(E4="","",INDEX(Knutepunkter!$D:$D,E4+1)) -> 9000 | L4: =IF(B4="","",SQRT((I4-F4)^2+(J4-G4)^2+(K4-H4)^2)) -> 3000 | M4: =IF(L4="","",L4/1000) -> 3 | P4: Bjelker stål [kg] | Q4: =IF(FORSIDE!B3="Stål",ROUND(Q2*FORSIDE!E19/1000000*7850,0),0) -> 0
A5: =Segmenter!A5 -> S4 | B5: =Segmenter!B5 -> 4 -> 5 | C5: =IF(B5="","",IF(AND(F5=I5,G5=J5,H5<>K5),"Søyle","Bjelke")) -> Søyle | D5: =IF(B5="","",VALUE(LEFT(B5,FIND(" -> ",B5)-1))) -> 4 | E5: =IF(B5="","",VALUE(MID(B5,FIND(" -> ",B5)+4,99))) -> 5 | F5: =IF(D5="","",INDEX(Knutepunkter!$B:$B,D5+1)) -> 354 | G5: =IF(D5="","",INDEX(Knutepunkter!$C:$C,D5+1)) -> 0 | H5: =IF(D5="","",INDEX(Knutepunkter!$D:$D,D5+1)) -> 9000 | I5: =IF(E5="","",INDEX(Knutepunkter!$B:$B,E5+1)) -> 354 | J5: =IF(E5="","",INDEX(Knutepunkter!$C:$C,E5+1)) -> 0 | K5: =IF(E5="","",INDEX(Knutepunkter!$D:$D,E5+1)) -> 12000 | L5: =IF(B5="","",SQRT((I5-F5)^2+(J5-G5)^2+(K5-H5)^2)) -> 3000 | M5: =IF(L5="","",L5/1000) -> 3 | P5: Bjelker limtre [m3] | Q5: =IF(FORSIDE!B3="Limtre",ROUND(Q2*FORSIDE!E20/1000000,3),0) -> 0
A6: =Segmenter!A6 -> S5 | B6: =Segmenter!B6 -> 5 -> 6 | C6: =IF(B6="","",IF(AND(F6=I6,G6=J6,H6<>K6),"Søyle","Bjelke")) -> Søyle | D6: =IF(B6="","",VALUE(LEFT(B6,FIND(" -> ",B6)-1))) -> 5 | E6: =IF(B6="","",VALUE(MID(B6,FIND(" -> ",B6)+4,99))) -> 6 | F6: =IF(D6="","",INDEX(Knutepunkter!$B:$B,D6+1)) -> 354 | G6: =IF(D6="","",INDEX(Knutepunkter!$C:$C,D6+1)) -> 0 | H6: =IF(D6="","",INDEX(Knutepunkter!$D:$D,D6+1)) -> 12000 | I6: =IF(E6="","",INDEX(Knutepunkter!$B:$B,E6+1)) -> 354 | J6: =IF(E6="","",INDEX(Knutepunkter!$C:$C,E6+1)) -> 0 | K6: =IF(E6="","",INDEX(Knutepunkter!$D:$D,E6+1)) -> 15000 | L6: =IF(B6="","",SQRT((I6-F6)^2+(J6-G6)^2+(K6-H6)^2)) -> 3000 | M6: =IF(L6="","",L6/1000) -> 3 | P6: Søyler stål [kg] | Q6: =IF(FORSIDE!B4="Stål",ROUND(Q3*FORSIDE!E21/1000000*7850,0),0) -> 0
A7: =Segmenter!A7 -> S6 | B7: =Segmenter!B7 -> 6 -> 7 | C7: =IF(B7="","",IF(AND(F7=I7,G7=J7,H7<>K7),"Søyle","Bjelke")) -> Søyle | D7: =IF(B7="","",VALUE(LEFT(B7,FIND(" -> ",B7)-1))) -> 6 | E7: =IF(B7="","",VALUE(MID(B7,FIND(" -> ",B7)+4,99))) -> 7 | F7: =IF(D7="","",INDEX(Knutepunkter!$B:$B,D7+1)) -> 354 | G7: =IF(D7="","",INDEX(Knutepunkter!$C:$C,D7+1)) -> 0 | H7: =IF(D7="","",INDEX(Knutepunkter!$D:$D,D7+1)) -> 15000 | I7: =IF(E7="","",INDEX(Knutepunkter!$B:$B,E7+1)) -> 354 | J7: =IF(E7="","",INDEX(Knutepunkter!$C:$C,E7+1)) -> 0 | K7: =IF(E7="","",INDEX(Knutepunkter!$D:$D,E7+1)) -> 18000 | L7: =IF(B7="","",SQRT((I7-F7)^2+(J7-G7)^2+(K7-H7)^2)) -> 3000 | M7: =IF(L7="","",L7/1000) -> 3 | P7: Søyler limtre [m3] | Q7: =IF(FORSIDE!B4="Limtre",ROUND(Q3*FORSIDE!E22/1000000,3),0) -> 0
A8: =Segmenter!A8 | B8: =Segmenter!B8 | C8: =IF(B8="","",IF(AND(F8=I8,G8=J8,H8<>K8),"Søyle","Bjelke")) | D8: =IF(B8="","",VALUE(LEFT(B8,FIND(" -> ",B8)-1))) | E8: =IF(B8="","",VALUE(MID(B8,FIND(" -> ",B8)+4,99))) | F8: =IF(D8="","",INDEX(Knutepunkter!$B:$B,D8+1)) | G8: =IF(D8="","",INDEX(Knutepunkter!$C:$C,D8+1)) | H8: =IF(D8="","",INDEX(Knutepunkter!$D:$D,D8+1)) | I8: =IF(E8="","",INDEX(Knutepunkter!$B:$B,E8+1)) | J8: =IF(E8="","",INDEX(Knutepunkter!$C:$C,E8+1)) | K8: =IF(E8="","",INDEX(Knutepunkter!$D:$D,E8+1)) | L8: =IF(B8="","",SQRT((I8-F8)^2+(J8-G8)^2+(K8-H8)^2)) | M8: =IF(L8="","",L8/1000)
A9: =Segmenter!A9 | B9: =Segmenter!B9 | C9: =IF(B9="","",IF(AND(F9=I9,G9=J9,H9<>K9),"Søyle","Bjelke")) | D9: =IF(B9="","",VALUE(LEFT(B9,FIND(" -> ",B9)-1))) | E9: =IF(B9="","",VALUE(MID(B9,FIND(" -> ",B9)+4,99))) | F9: =IF(D9="","",INDEX(Knutepunkter!$B:$B,D9+1)) | G9: =IF(D9="","",INDEX(Knutepunkter!$C:$C,D9+1)) | H9: =IF(D9="","",INDEX(Knutepunkter!$D:$D,D9+1)) | I9: =IF(E9="","",INDEX(Knutepunkter!$B:$B,E9+1)) | J9: =IF(E9="","",INDEX(Knutepunkter!$C:$C,E9+1)) | K9: =IF(E9="","",INDEX(Knutepunkter!$D:$D,E9+1)) | L9: =IF(B9="","",SQRT((I9-F9)^2+(J9-G9)^2+(K9-H9)^2)) | M9: =IF(L9="","",L9/1000)
A10: =Segmenter!A10 | B10: =Segmenter!B10 | C10: =IF(B10="","",IF(AND(F10=I10,G10=J10,H10<>K10),"Søyle","Bjelke")) | D10: =IF(B10="","",VALUE(LEFT(B10,FIND(" -> ",B10)-1))) | E10: =IF(B10="","",VALUE(MID(B10,FIND(" -> ",B10)+4,99))) | F10: =IF(D10="","",INDEX(Knutepunkter!$B:$B,D10+1)) | G10: =IF(D10="","",INDEX(Knutepunkter!$C:$C,D10+1)) | H10: =IF(D10="","",INDEX(Knutepunkter!$D:$D,D10+1)) | I10: =IF(E10="","",INDEX(Knutepunkter!$B:$B,E10+1)) | J10: =IF(E10="","",INDEX(Knutepunkter!$C:$C,E10+1)) | K10: =IF(E10="","",INDEX(Knutepunkter!$D:$D,E10+1)) | L10: =IF(B10="","",SQRT((I10-F10)^2+(J10-G10)^2+(K10-H10)^2)) | M10: =IF(L10="","",L10/1000)
A11: =Segmenter!A11 | B11: =Segmenter!B11 | C11: =IF(B11="","",IF(AND(F11=I11,G11=J11,H11<>K11),"Søyle","Bjelke")) | D11: =IF(B11="","",VALUE(LEFT(B11,FIND(" -> ",B11)-1))) | E11: =IF(B11="","",VALUE(MID(B11,FIND(" -> ",B11)+4,99))) | F11: =IF(D11="","",INDEX(Knutepunkter!$B:$B,D11+1)) | G11: =IF(D11="","",INDEX(Knutepunkter!$C:$C,D11+1)) | H11: =IF(D11="","",INDEX(Knutepunkter!$D:$D,D11+1)) | I11: =IF(E11="","",INDEX(Knutepunkter!$B:$B,E11+1)) | J11: =IF(E11="","",INDEX(Knutepunkter!$C:$C,E11+1)) | K11: =IF(E11="","",INDEX(Knutepunkter!$D:$D,E11+1)) | L11: =IF(B11="","",SQRT((I11-F11)^2+(J11-G11)^2+(K11-H11)^2)) | M11: =IF(L11="","",L11/1000)
A12: =Segmenter!A12 -> S11 | B12: =Segmenter!B12 -> 12 -> 13 | C12: =IF(B12="","",IF(AND(F12=I12,G12=J12,H12<>K12),"Søyle","Bjelke")) -> Søyle | D12: =IF(B12="","",VALUE(LEFT(B12,FIND(" -> ",B12)-1))) -> 12 | E12: =IF(B12="","",VALUE(MID(B12,FIND(" -> ",B12)+4,99))) -> 13 | F12: =IF(D12="","",INDEX(Knutepunkter!$B:$B,D12+1)) -> 354 | G12: =IF(D12="","",INDEX(Knutepunkter!$C:$C,D12+1)) -> 8000 | H12: =IF(D12="","",INDEX(Knutepunkter!$D:$D,D12+1)) -> 0 | I12: =IF(E12="","",INDEX(Knutepunkter!$B:$B,E12+1)) -> 354 | J12: =IF(E12="","",INDEX(Knutepunkter!$C:$C,E12+1)) -> 8000 | K12: =IF(E12="","",INDEX(Knutepunkter!$D:$D,E12+1)) -> 3000 | L12: =IF(B12="","",SQRT((I12-F12)^2+(J12-G12)^2+(K12-H12)^2)) -> 3000 | M12: =IF(L12="","",L12/1000) -> 3
A13: =Segmenter!A13 -> S12 | B13: =Segmenter!B13 -> 13 -> 14 | C13: =IF(B13="","",IF(AND(F13=I13,G13=J13,H13<>K13),"Søyle","Bjelke")) -> Søyle | D13: =IF(B13="","",VALUE(LEFT(B13,FIND(" -> ",B13)-1))) -> 13 | E13: =IF(B13="","",VALUE(MID(B13,FIND(" -> ",B13)+4,99))) -> 14 | F13: =IF(D13="","",INDEX(Knutepunkter!$B:$B,D13+1)) -> 354 | G13: =IF(D13="","",INDEX(Knutepunkter!$C:$C,D13+1)) -> 8000 | H13: =IF(D13="","",INDEX(Knutepunkter!$D:$D,D13+1)) -> 3000 | I13: =IF(E13="","",INDEX(Knutepunkter!$B:$B,E13+1)) -> 354 | J13: =IF(E13="","",INDEX(Knutepunkter!$C:$C,E13+1)) -> 8000 | K13: =IF(E13="","",INDEX(Knutepunkter!$D:$D,E13+1)) -> 6000 | L13: =IF(B13="","",SQRT((I13-F13)^2+(J13-G13)^2+(K13-H13)^2)) -> 3000 | M13: =IF(L13="","",L13/1000) -> 3
A14: =Segmenter!A14 -> S13 | B14: =Segmenter!B14 -> 14 -> 15 | C14: =IF(B14="","",IF(AND(F14=I14,G14=J14,H14<>K14),"Søyle","Bjelke")) -> Søyle | D14: =IF(B14="","",VALUE(LEFT(B14,FIND(" -> ",B14)-1))) -> 14 | E14: =IF(B14="","",VALUE(MID(B14,FIND(" -> ",B14)+4,99))) -> 15 | F14: =IF(D14="","",INDEX(Knutepunkter!$B:$B,D14+1)) -> 354 | G14: =IF(D14="","",INDEX(Knutepunkter!$C:$C,D14+1)) -> 8000 | H14: =IF(D14="","",INDEX(Knutepunkter!$D:$D,D14+1)) -> 6000 | I14: =IF(E14="","",INDEX(Knutepunkter!$B:$B,E14+1)) -> 354 | J14: =IF(E14="","",INDEX(Knutepunkter!$C:$C,E14+1)) -> 8000 | K14: =IF(E14="","",INDEX(Knutepunkter!$D:$D,E14+1)) -> 9000 | L14: =IF(B14="","",SQRT((I14-F14)^2+(J14-G14)^2+(K14-H14)^2)) -> 3000 | M14: =IF(L14="","",L14/1000) -> 3
A15: =Segmenter!A15 -> S14 | B15: =Segmenter!B15 -> 15 -> 16 | C15: =IF(B15="","",IF(AND(F15=I15,G15=J15,H15<>K15),"Søyle","Bjelke")) -> Søyle | D15: =IF(B15="","",VALUE(LEFT(B15,FIND(" -> ",B15)-1))) -> 15 | E15: =IF(B15="","",VALUE(MID(B15,FIND(" -> ",B15)+4,99))) -> 16 | F15: =IF(D15="","",INDEX(Knutepunkter!$B:$B,D15+1)) -> 354 | G15: =IF(D15="","",INDEX(Knutepunkter!$C:$C,D15+1)) -> 8000 | H15: =IF(D15="","",INDEX(Knutepunkter!$D:$D,D15+1)) -> 9000 | I15: =IF(E15="","",INDEX(Knutepunkter!$B:$B,E15+1)) -> 354 | J15: =IF(E15="","",INDEX(Knutepunkter!$C:$C,E15+1)) -> 8000 | K15: =IF(E15="","",INDEX(Knutepunkter!$D:$D,E15+1)) -> 12000 | L15: =IF(B15="","",SQRT((I15-F15)^2+(J15-G15)^2+(K15-H15)^2)) -> 3000 | M15: =IF(L15="","",L15/1000) -> 3
A16: =Segmenter!A16 -> S15 | B16: =Segmenter!B16 -> 16 -> 17 | C16: =IF(B16="","",IF(AND(F16=I16,G16=J16,H16<>K16),"Søyle","Bjelke")) -> Søyle | D16: =IF(B16="","",VALUE(LEFT(B16,FIND(" -> ",B16)-1))) -> 16 | E16: =IF(B16="","",VALUE(MID(B16,FIND(" -> ",B16)+4,99))) -> 17 | F16: =IF(D16="","",INDEX(Knutepunkter!$B:$B,D16+1)) -> 354 | G16: =IF(D16="","",INDEX(Knutepunkter!$C:$C,D16+1)) -> 8000 | H16: =IF(D16="","",INDEX(Knutepunkter!$D:$D,D16+1)) -> 12000 | I16: =IF(E16="","",INDEX(Knutepunkter!$B:$B,E16+1)) -> 354 | J16: =IF(E16="","",INDEX(Knutepunkter!$C:$C,E16+1)) -> 8000 | K16: =IF(E16="","",INDEX(Knutepunkter!$D:$D,E16+1)) -> 15000 | L16: =IF(B16="","",SQRT((I16-F16)^2+(J16-G16)^2+(K16-H16)^2)) -> 3000 | M16: =IF(L16="","",L16/1000) -> 3
A17: =Segmenter!A17 -> S16 | B17: =Segmenter!B17 -> 17 -> 18 | C17: =IF(B17="","",IF(AND(F17=I17,G17=J17,H17<>K17),"Søyle","Bjelke")) -> Søyle | D17: =IF(B17="","",VALUE(LEFT(B17,FIND(" -> ",B17)-1))) -> 17 | E17: =IF(B17="","",VALUE(MID(B17,FIND(" -> ",B17)+4,99))) -> 18 | F17: =IF(D17="","",INDEX(Knutepunkter!$B:$B,D17+1)) -> 354 | G17: =IF(D17="","",INDEX(Knutepunkter!$C:$C,D17+1)) -> 8000 | H17: =IF(D17="","",INDEX(Knutepunkter!$D:$D,D17+1)) -> 15000 | I17: =IF(E17="","",INDEX(Knutepunkter!$B:$B,E17+1)) -> 354 | J17: =IF(E17="","",INDEX(Knutepunkter!$C:$C,E17+1)) -> 8000 | K17: =IF(E17="","",INDEX(Knutepunkter!$D:$D,E17+1)) -> 18000 | L17: =IF(B17="","",SQRT((I17-F17)^2+(J17-G17)^2+(K17-H17)^2)) -> 3000 | M17: =IF(L17="","",L17/1000) -> 3
A18: =Segmenter!A18 | B18: =Segmenter!B18 | C18: =IF(B18="","",IF(AND(F18=I18,G18=J18,H18<>K18),"Søyle","Bjelke")) | D18: =IF(B18="","",VALUE(LEFT(B18,FIND(" -> ",B18)-1))) | E18: =IF(B18="","",VALUE(MID(B18,FIND(" -> ",B18)+4,99))) | F18: =IF(D18="","",INDEX(Knutepunkter!$B:$B,D18+1)) | G18: =IF(D18="","",INDEX(Knutepunkter!$C:$C,D18+1)) | H18: =IF(D18="","",INDEX(Knutepunkter!$D:$D,D18+1)) | I18: =IF(E18="","",INDEX(Knutepunkter!$B:$B,E18+1)) | J18: =IF(E18="","",INDEX(Knutepunkter!$C:$C,E18+1)) | K18: =IF(E18="","",INDEX(Knutepunkter!$D:$D,E18+1)) | L18: =IF(B18="","",SQRT((I18-F18)^2+(J18-G18)^2+(K18-H18)^2)) | M18: =IF(L18="","",L18/1000)
A19: =Segmenter!A19 | B19: =Segmenter!B19 | C19: =IF(B19="","",IF(AND(F19=I19,G19=J19,H19<>K19),"Søyle","Bjelke")) | D19: =IF(B19="","",VALUE(LEFT(B19,FIND(" -> ",B19)-1))) | E19: =IF(B19="","",VALUE(MID(B19,FIND(" -> ",B19)+4,99))) | F19: =IF(D19="","",INDEX(Knutepunkter!$B:$B,D19+1)) | G19: =IF(D19="","",INDEX(Knutepunkter!$C:$C,D19+1)) | H19: =IF(D19="","",INDEX(Knutepunkter!$D:$D,D19+1)) | I19: =IF(E19="","",INDEX(Knutepunkter!$B:$B,E19+1)) | J19: =IF(E19="","",INDEX(Knutepunkter!$C:$C,E19+1)) | K19: =IF(E19="","",INDEX(Knutepunkter!$D:$D,E19+1)) | L19: =IF(B19="","",SQRT((I19-F19)^2+(J19-G19)^2+(K19-H19)^2)) | M19: =IF(L19="","",L19/1000)
... A6611: =Segmenter!A6611 | B6611: =Segmenter!B6611 | C6611: =IF(B6611="","",IF(AND(F6611=I6611,G6611=J6611,H6611<>K6611),"Søyle","Bjelke")) | D6611: =IF(B6611="","",VALUE(LEFT(B6611,FIND(" -> ",B6611)-1))) | E6611: =IF(B6611="","",VALUE(MID(B6611,FIND(" -> ",B6611)+4,99))) | F6611: =IF(D6611="","",INDEX(Knutepunkter!$B:$B,D6611+1)) | G6611: =IF(D6611="","",INDEX(Knutepunkter!$C:$C,D6611+1)) | H6611: =IF(D6611="","",INDEX(Knutepunkter!$D:$D,D6611+1)) | I6611: =IF(E6611="","",INDEX(Knutepunkter!$B:$B,E6611+1)) | J6611: =IF(E6611="","",INDEX(Knutepunkter!$C:$C,E6611+1)) | K6611: =IF(E6611="","",INDEX(Knutepunkter!$D:$D,E6611+1)) | L6611: =IF(B6611="","",SQRT((I6611-F6611)^2+(J6611-G6611)^2+(K6611-H6611)^2)) | M6611: =IF(L6611="","",L6611/1000)
